Workbook

Sheet Cover
A16: TIMES-Ireland Model
A19: Document type: | B19: New Technologies
A20: Sector(s): | B20: Power sector (PWR)
A21: Purpose: | B21: Specify techno-economic data for new generation technologies
A23: Original developer(s): | B23: Xiufeng Yue (UCC, xiufeng.yue@ucc.ie)
B24: James Glynn (UCC, james.glynn@ucc.ie)
A26: Current maintainer(s): | B26: Olexandr Balyk (UCC, olexandr.balyk@ucc.ie)
A29: Part of TIM version: | B29: 1
A30: Model repository: | B30: https://github.com/MaREI-EPMG/TIMES-Ireland-model
A31: Licence: | B31: CC BY-NC-SA 4.0 (unless specified otherwise)
B32: https://creativecommons.org/licenses/by-nc-sa/4.0/

Sheet ELC_EGP
A1: Electricity Generators Database
A2: Source: ETRI 2014 (https://setis.ec.europa.eu/publications/jrc-setis-reports/etri-2014 )
F3: ~FI_T: MEUR2015 | AL3: ~FI_Process
A4: TechName | B4: *Cost data Source | C4: *Effieiency Data source | D4: *TechDesc | E4: Comm-IN | F4: Comm-OUT | G4: EFF | H4: EFF~2020 | I4: EFF~2030 | J4: EFF~2040 | K4: EFF~2050 | L4: Start | M4: INVCOST~2015 | N4: INVCOST~2020 | O4: INVCOST~2030 | P4: INVCOST~2040 | Q4: INVCOST~2050 | R4: FIXOM | S4: FIXOM~2020 | T4: FIXOM~2030 | U4: FIXOM~2040 | V4: FIXOM~2050 | W4: VAROM | X4: VAROM~2020 | Y4: VAROM~2030 | Z4: VAROM~2040 | AA4: VAROM~2050 | AB4: LIFE | AC4: LIFE~2020 | AD4: LIFE~2030 | AE4: Cap2Act | AF4: AFA | AG4: AFA~2020 | AH4: AFA~2030 | AI4: AFA~2040 | AJ4: AFA~2050 | AL4: Sets | AM4: TechName | AN4: TechDesc | AO4: Tact | AP4: Tcap | AQ4: Tslvl | AR4: PrimaryCG | AS4: Vintage
A5: *Technology Name | D5: Technology Description | E5: Input Commodity | F5: Output Commodity | G5: Efficiency | M5: CAPEX REF (€2013/kW) | R5: FOM (€2013/kW) | W5: VOM (€2013/GJ) | AB5: Technical life | AF5: Max. capacity factor | AL5: *Process Set Membership | AM5: Technology Name | AN5: Technology Description | AO5: Activity Unit | AP5: Capacity Unit | AQ5: TimeSlice Level | AR5: Primary CommGrp | AS5: Vintage Tracking
A6: *P-RNW-WIN-OF02 | B6: ETRI2018 | D6: ="PWR "&AW6&" new" -> PWR Offshore wind new | E6: PWRWIN | F6: ELCC | G6: 1 | L6: 2019 | M6: =3118 -> 3118 | Q6: 2827 | R6: 128.39 | S6: 92.16 | T6: 77.4 | U6: 66.64 | V6: 52.44 | AB6: 20 | AC6: 25 | AD6: 30 | AE6: 31.536 | AL6: ELE | AM6: P-RNW-WIN-OF02 | AN6: =D6 -> PWR Offshore wind new | AO6: PJ | AP6: GW | AQ6: DAYNITE | AW6: Offshore wind
A7: P-RNW-SOL-PV01 | B7: ETRI2018 | D7: ="PWR "&AW7&" new" -> PWR Commercial solar PV system 0.1-2 MW new | E7: PWRSOL | F7: ELCC | G7: 1 | L7: 2019 | M7: 500 | Q7: 670 | R7: 27.5 | S7: 22.5 | T7: 20.25 | U7: 19 | V7: 18 | AB7: 25 | AE7: 31.536 | AL7: ELE | AM7: =A7 -> P-RNW-SOL-PV01 | AN7: =D7 -> PWR Commercial solar PV system 0.1-2 MW new | AO7: PJ | AP7: GW | AQ7: DAYNITE | AW7: Commercial solar PV system 0.1-2 MW
A8: P-RNW-SOL-PV02 | B8: ETRI2018 | D8: ="PWR "&AW8&" new" -> PWR Commercial solar PV >2 MW without tracking new | E8: PWRSOL | F8: ELCC | G8: 1 | L8: 2019 | M8: =+M7 -> 500 | Q8: =+Q7 -> 670 | R8: 16.66 | S8: 13.6 | T8: 10.88 | U8: 9.86 | V8: 8.84 | AB8: 25 | AE8: 31.536 | AL8: ELE | AM8: =A8 -> P-RNW-SOL-PV02 | AN8: =D8 -> PWR Commercial solar PV >2 MW without tracking new | AO8: PJ | AP8: GW | AQ8: DAYNITE | AW8: Commercial solar PV >2 MW without tracking
A9: P-RNW-SOL-PV03 | B9: ETRI2018 | D9: ="PWR "&AW9&" new" -> PWR Commercial solar PV >2 MW with tracking new | E9: PWRSOL | F9: ELCC | G9: 1 | L9: 2019 | M9: =+M8 -> 500 | Q9: =+Q8 -> 670 | R9: 21.75 | S9: 16.5 | T9: 13.35 | U9: 11.85 | V9: 10.65 | AB9: 25 | AE9: 31.536 | AL9: ELE | AM9: =A9 -> P-RNW-SOL-PV03 | AN9: =D9 -> PWR Commercial solar PV >2 MW with tracking new | AO9: PJ | AP9: GW | AQ9: DAYNITE | AW9: Commercial solar PV >2 MW with tracking
A10: P-RNW-SOL-CSP04 | B10: ETRI2014 | D10: ="PWR "&AW10&" new" -> PWR Solar thermal electricity power plants without thermal storage (power/heat=0.38) new | E10: PWRSOL | F10: ELCC | G10: 0.36 | L10: 2019 | M10: 5600 | N10: 4500 | O10: 3800 | P10: 3500 | Q10: 3400 | R10: 224 | S10: 180 | T10: 152 | U10: 140 | V10: 136 | W10: 0.448 | X10: 0.36 | Y10: 0.304 | Z10: 0.28 | AA10: 0.272 | AB10: 30 | AE10: 31.536 | AF10: 0.42 | AL10: ELE | AM10: =A10 -> P-RNW-SOL-CSP04 | AN10: =D10 -> PWR Solar thermal electricity power plants without thermal storage (power/heat=0.38) new | AO10: PJ | AP10: GW | AQ10: DAYNITE | AW10: Solar thermal electricity power plants without thermal storage (power/heat=0.38)
A11: P-RNW-HYD-DAM01 | B11: ETRI2018 | D11: ="PWR "&AW11&" new" -> PWR Hydropower dam and reservoir, >100 MW new | E11: PWRHYD | F11: ELCC | G11: 1 | L11: 2019 | M11: =VLOOKUP($A11,ETRI_Cost!$A:$I,5,FALSE) -> 3500 | N11: =VLOOKUP($A11,ETRI_Cost!$A:$I,6,FALSE) -> 3500 | O11: =VLOOKUP($A11,ETRI_Cost!$A:$I,7,FALSE) -> 3490 | P11: =VLOOKUP($A11,ETRI_Cost!$A:$I,8,FALSE) -> 3480 | Q11: =VLOOKUP($A11,ETRI_Cost!$A:$I,9,FALSE) -> 3470 | R11: 22 | S11: 22 | T11: 22 | U11: 22 | V11: 22 | W11: 0.066 | X11: 0.066 | Y11: 0.066 | Z11: 0.066 | AA11: 0.066 | AB11: 60 | AE11: 31.536 | AF11: 0.35 | AL11: ELE | AM11: =A11 -> P-RNW-HYD-DAM01 | AN11: =D11 -> PWR Hydropower dam and reservoir, >100 MW new | AO11: PJ | AP11: GW | AQ11: DAYNITE | AW11: Hydropower dam and reservoir, >100 MW
A12: P-RNW-HYD-DAM02 | B12: ETRI2018 | D12: ="PWR "&AW12&" new" -> PWR Hydropower dam and reservoir, 10-100 MW new | E12: PWRHYD | F12: ELCC | G12: 1 | L12: 2019 | M12: =VLOOKUP($A12,ETRI_Cost!$A:$I,5,FALSE) -> 4000 | N12: =VLOOKUP($A12,ETRI_Cost!$A:$I,6,FALSE) -> 4000 | O12: =VLOOKUP($A12,ETRI_Cost!$A:$I,7,FALSE) -> 3980 | P12: =VLOOKUP($A12,ETRI_Cost!$A:$I,8,FALSE) -> 3970 | Q12: =VLOOKUP($A12,ETRI_Cost!$A:$I,9,FALSE) -> 3970 | R12: 49.5 | S12: 50.4 | T12: 50.55 | U12: 50.55 | V12: 50.55 | W12: 0.165 | X12: 0.168 | Y12: 0.1685 | Z12: 0.1685 | AA12: 0.1685 | AB12: 60 | AE12: 31.536 | AF12: 0.4 | AL12: ELE | AM12: =A12 -> P-RNW-HYD-DAM02 | AN12: =D12 -> PWR Hydropower dam and reservoir, 10-100 MW new | AO12: PJ | AP12: GW | AQ12: DAYNITE | AW12: Hydropower dam and reservoir, 10-100 MW
A13: P-RNW-HYD-DAM03 | B13: ETRI2018 | D13: ="PWR "&AW13&" new" -> PWR Hydropower dam and reservoir, <10 MW new | E13: PWRHYD | F13: ELCC | G13: 1 | L13: 2019 | M13: =VLOOKUP($A13,ETRI_Cost!$A:$I,5,FALSE) -> 5000 | N13: =VLOOKUP($A13,ETRI_Cost!$A:$I,6,FALSE) -> 5000 | O13: =VLOOKUP($A13,ETRI_Cost!$A:$I,7,FALSE) -> 4980 | P13: =VLOOKUP($A13,ETRI_Cost!$A:$I,8,FALSE) -> 4970 | Q13: =VLOOKUP($A13,ETRI_Cost!$A:$I,9,FALSE) -> 4960 | R13: 66 | S13: 67.2 | T13: 67.5 | U13: 67.5 | V13: 67.5 | W13: 0.22 | X13: 0.224 | Y13: 0.225 | Z13: 0.225 | AA13: 0.225 | AB13: 60 | AE13: 31.536 | AF13: 0.37 | AL13: ELE | AM13: =A13 -> P-RNW-HYD-DAM03 | AN13: =D13 -> PWR Hydropower dam and reservoir, <10 MW new | AO13: PJ | AP13: GW | AQ13: DAYNITE | AW13: Hydropower dam and reservoir, <10 MW
A14: P-RNW-HYD-ROR04 | B14: ETRI2018 | D14: ="PWR "&AW14&" new" -> PWR Hydropower run-of-a-river new | E14: PWRHYD | F14: ELCC | G14: 1 | L14: 2019 | M14: =VLOOKUP($A14,ETRI_Cost!$A:$I,5,FALSE) -> 3000 | N14: =VLOOKUP($A14,ETRI_Cost!$A:$I,6,FALSE) -> 3000 | O14: =VLOOKUP($A14,ETRI_Cost!$A:$I,7,FALSE) -> 2990 | P14: =VLOOKUP($A14,ETRI_Cost!$A:$I,8,FALSE) -> 2980 | Q14: =VLOOKUP($A14,ETRI_Cost!$A:$I,9,FALSE) -> 2970 | R14: 82.5 | S14: 84 | T14: 84.3 | U14: 84.3 | V14: 84.3 | W14: 0.275 | X14: 0.28 | Y14: 0.281 | Z14: 0.281 | AA14: 0.281 | AB14: 60 | AE14: 31.536 | AF14: 0.37 | AL14: ELE | AM14: =A14 -> P-RNW-HYD-ROR04 | AN14: =D14 -> PWR Hydropower run-of-a-river new | AO14: PJ | AP14: GW | AQ14: DAYNITE | AW14: Hydropower run-of-a-river
A15: P-RNW-GEO01 | B15: ETRI2018 | C15: ETRI2014 | D15: ="PWR "&AW15&" new" -> PWR Flash power plant extracting fluid from hydrothermal system at 2.5 km depth new | E15: PWRGEO | F15: ELCC | G15: 0.1 | H15: 0.1 | I15: 0.1 | J15: 0.1 | K15: 0.1 | L15: 2019 | M15: =VLOOKUP($A15,ETRI_Cost!$A:$I,5,FALSE) -> 3540 | N15: =VLOOKUP($A15,ETRI_Cost!$A:$I,6,FALSE) -> 3350 | O15: =VLOOKUP($A15,ETRI_Cost!$A:$I,7,FALSE) -> 3150 | P15: =VLOOKUP($A15,ETRI_Cost!$A:$I,8,FALSE) -> 3020 | Q15: =VLOOKUP($A15,ETRI_Cost!$A:$I,9,FALSE) -> 2910 | R15: 77.42 | S15: 79.52 | T15: 80.46 | U15: 80.4 | V15: 79.42 | AB15: 30 | AE15: 31.536 | AF15: 0.95 | AL15: ELE | AM15: =A15 -> P-RNW-GEO01 | AN15: =D15 -> PWR Flash power plant extracting fluid from hydrothermal system at 2.5 km depth new | AO15: PJ | AP15: GW | AQ15: DAYNITE | AW15: Flash power plant extracting fluid from hydrothermal system at 2.5 km depth
A16: P-RNW-GEO02 | B16: ETRI2018 | C16: ETRI2014 | D16: ="PWR "&AW16&" new" -> PWR Organic Rankine Cycle hydrothermal system. new | E16: PWRGEO | F16: ELCC | G16: 0.1 | H16: 0.1 | I16: 0.1 | J16: 0.1 | K16: 0.1 | L16: 2019 | M16: =VLOOKUP($A16,ETRI_Cost!$A:$I,5,FALSE) -> 6970 | N16: =VLOOKUP($A16,ETRI_Cost!$A:$I,6,FALSE) -> 6600 | O16: =VLOOKUP($A16,ETRI_Cost!$A:$I,7,FALSE) -> 6190 | P16: =VLOOKUP($A16,ETRI_Cost!$A:$I,8,FALSE) -> 5950 | Q16: =VLOOKUP($A16,ETRI_Cost!$A:$I,9,FALSE) -> 5720 | R16: 146.37 | S16: 145.2 | T16: 143.52 | U16: 146.75 | V16: 148.77 | AB16: 30 | AE16: 31.536 | AF16: 0.95 | AL16: ELE | AM16: =A16 -> P-RNW-GEO02 | AN16: =D16 -> PWR Organic Rankine Cycle hydrothermal system. new | AO16: PJ | AP16: GW | AQ16: DAYNITE | AW16: Organic Rankine Cycle hydrothermal system.
A17: P-RNW-GEO03 | B17: ETRI2014 | C17: ETRI2014 | D17: ="PWR "&AW17&" new" -> PWR Organic Rankine Cycle Enhanced Geothermal System at 5.5 km depth new | E17: PWRGEO | F17: ELCC | G17: 0.1 | H17: 0.1 | I17: 0.1 | J17: 0.1 | K17: 0.1 | L17: 2019 | M17: 12600 | N17: 10300 | O17: 9000 | P17: 8600 | Q17: 8200 | R17: 226.8 | S17: 185.4 | T17: 171 | U17: 163.4 | V17: 155.8 | AB17: 30 | AE17: 31.536 | AF17: 0.95 | AL17: ELE | AM17: =A17 -> P-RNW-GEO03 | AN17: =D17 -> PWR Organic Rankine Cycle Enhanced Geothermal System at 5.5 km depth new | AO17: PJ | AP17: GW | AQ17: DAYNITE | AW17: Organic Rankine Cycle Enhanced Geothermal System at 5.5 km depth
A18: P-RNW-OCE-WAV01 | B18: ETRI2018 | D18: ="PWR "&AW18&" new" -> PWR Wave energy new | E18: PWROCE | F18: ELCC | G18: 1 | L18: 2019 | M18: =VLOOKUP($A18,ETRI_Cost!$A:$I,5,FALSE) -> 7910 | N18: =VLOOKUP($A18,ETRI_Cost!$A:$I,6,FALSE) -> 6310 | O18: =VLOOKUP($A18,ETRI_Cost!$A:$I,7,FALSE) -> 5320 | P18: =VLOOKUP($A18,ETRI_Cost!$A:$I,8,FALSE) -> 4040 | Q18: =VLOOKUP($A18,ETRI_Cost!$A:$I,9,FALSE) -> 3240 | R18: 326.88 | S18: 237.39 | T18: 210.56 | U18: 153.7 | V18: 133.4 | AB18: 20 | AE18: 31.536 | AF18: 0.36 | AL18: ELE | AM18: =A18 -> P-RNW-OCE-WAV01 | AN18: =D18 -> PWR Wave energy new | AO18: PJ | AP18: GW | AQ18: DAYNITE | AW18: Wave energy
A19: P-RNW-OCE-TID02 | B19: ETRI2018 | D19: ="PWR "&AW19&" new" -> PWR Tidal energy new | E19: PWROCE | F19: ELCC | G19: 1 | L19: 2019 | M19: =VLOOKUP($A19,ETRI_Cost!$A:$I,5,FALSE) -> 7840 | N19: =VLOOKUP($A19,ETRI_Cost!$A:$I,6,FALSE) -> 6260 | O19: =VLOOKUP($A19,ETRI_Cost!$A:$I,7,FALSE) -> 5270 | P19: =VLOOKUP($A19,ETRI_Cost!$A:$I,8,FALSE) -> 4000 | Q19: =VLOOKUP($A19,ETRI_Cost!$A:$I,9,FALSE) -> 3210 | R19: 363.8 | S19: 158.4 | T19: 117.8 | U19: 90.3 | V19: 93.1 | AB19: 20 | AE19: 31.536 | AF19: 0.36 | AL19: ELE | AM19: =A19 -> P-RNW-OCE-TID02 | AN19: =D19 -> PWR Tidal energy new | AO19: PJ | AP19: GW | AQ19: DAYNITE | AW19: Tidal energy
A20: P-TH-OCGT-GAS01 | B20: ETRI2014 | D20: ="PWR "&AW20&" new" -> PWR Open-Cycle Gas Turbine conventional new | E20: PWRGAS | F20: ELCC | G20: 0.38 | L20: 2019 | M20: 770 | R20: 7.7 | AB20: 30 | AE20: 31.536 | AF20: 0.95 | AL20: ELE | AM20: =A20 -> P-TH-OCGT-GAS01 | AN20: =D20 -> PWR Open-Cycle Gas Turbine conventional new | AO20: PJ | AP20: GW | AQ20: DAYNITE | AW20: Open-Cycle Gas Turbine conventional
A21: P-TH-OCGT-GAS02 | B21: ETRI2014 | D21: ="PWR "&AW21&" new" -> PWR Open Cycle Gas Turbine advanced new | E21: PWRGAS | F21: ELCC | G21: 0.4 | H21: 0.4 | I21: 0.43 | J21: 0.44 | K21: 0.45 | L21: 2019 | M21: 550 | N21: 550 | O21: 550 | P21: 550 | Q21: 550 | R21: 16.5 | S21: 16.5 | T21: 16.5 | U21: 16.5 | V21: 16.5 | W21: 0.0605 | X21: 0.0605 | Y21: 0.0605 | Z21: 0.0605 | AA21: 0.0605 | AB21: 30 | AE21: 31.536 | AF21: 0.95 | AL21: ELE | AM21: =A21 -> P-TH-OCGT-GAS02 | AN21: =D21 -> PWR Open Cycle Gas Turbine advanced new | AO21: PJ | AP21: GW | AQ21: DAYNITE | AW21: Open Cycle Gas Turbine advanced
A22: P-TH-CCGT-GAS03 | B22: ETRI2014 | C22: ETRI2014 | D22: ="PWR "&AW22&" new" -> PWR Combined Cycle Gas Turbine advanced new | E22: PWRGAS | F22: ELCC | G22: 0.58 | H22: 0.6 | I22: 0.62 | J22: 0.62 | K22: 0.63 | L22: 2019 | M22: 850 | N22: 850 | O22: 850 | P22: 850 | Q22: 850 | R22: 21.25 | S22: 21.25 | T22: 21.25 | U22: 21.25 | V22: 21.25 | W22: 0.017 | X22: 0.017 | Y22: 0.017 | Z22: 0.017 | AA22: 0.017 | AB22: 30 | AE22: 31.536 | AF22: 0.9 | AL22: ELE | AM22: =A22 -> P-TH-CCGT-GAS03 | AN22: =D22 -> PWR Combined Cycle Gas Turbine advanced new | AO22: PJ | AP22: GW | AQ22: DAYNITE | AW22: Combined Cycle Gas Turbine advanced
A23: P-TH-SC-COA01 | B23: ETRI2014 | C23: ETRI2014 | D23: ="PWR "&AW23&" new" -> PWR Pulverised coal supercritical new | E23: PWRCOA | F23: ELCC | G23: 0.45 | H23: 0.46 | I23: 0.48 | J23: 0.48 | K23: 0.48 | L23: 2019 | M23: 1600 | N23: 1600 | O23: 1600 | P23: 1600 | Q23: 1600 | R23: 40 | S23: 40 | T23: 40 | U23: 40 | V23: 40 | W23: 0.0576 | X23: 0.0576 | Y23: 0.0576 | Z23: 0.0576 | AA23: 0.0576 | AB23: 40 | AE23: 31.536 | AF23: 0.9 | AL23: ELE | AM23: =A23 -> P-TH-SC-COA01 | AN23: =D23 -> PWR Pulverised coal supercritical new | AO23: PJ | AP23: GW | AQ23: DAYNITE | AW23: Pulverised coal supercritical
A24: P-TH-FB-PEA01 | B24: ETRI2014 | C24: ETRI2014 | D24: ="PWR "&AW24&" new" -> PWR Pulverised peat supercritical new | E24: PWRPEA | F24: ELCC | G24: 0.42 | H24: 0.45 | I24: 0.47 | J24: 0.47 | K24: 0.47 | L24: 2019 | M24: 2000 | N24: 2000 | O24: 2000 | P24: 2000 | Q24: 2000 | R24: 50 | S24: 50 | T24: 50 | U24: 50 | V24: 50 | W24: 0.09 | X24: 0.09 | Y24: 0.09 | Z24: 0.09 | AA24: 0.09 | AB24: 40 | AE24: 31.536 | AF24: 0.9 | AL24: ELE | AM24: =A24 -> P-TH-FB-PEA01 | AN24: =D24 -> PWR Pulverised peat supercritical new | AO24: PJ | AP24: GW | AQ24: DAYNITE | AW24: Pulverised peat supercritical
A25: P-TH-SC-PEA02 | B25: ETRI2014 | C25: ETRI2014 | D25: ="PWR "&AW25&" new" -> PWR Supercritical fluidized bed peat new | E25: PWRPEA | F25: ELCC | G25: 0.42 | H25: 0.43 | I25: 0.45 | J25: 0.45 | K25: 0.45 | L25: 2019 | M25: 1900 | N25: 1900 | O25: 1900 | P25: 1900 | Q25: 1900 | R25: 38 | S25: 38 | T25: 38 | U25: 38 | V25: 38 | W25: 0.114 | X25: 0.114 | Y25: 0.114 | Z25: 0.114 | AA25: 0.114 | AB25: 40 | AE25: 31.536 | AF25: 0.85 | AL25: ELE | AM25: =A25 -> P-TH-SC-PEA02 | AN25: =D25 -> PWR Supercritical fluidized bed peat new | AO25: PJ | AP25: GW | AQ25: DAYNITE | AW25: Supercritical fluidized bed peat
A26: P-TH-IGCC-COA03 | B26: ETRI2014 | C26: ETRI2014 | D26: ="PWR "&AW26&" new" -> PWR Integrated Gasification Combined Cycle coal new | E26: PWRCOA | F26: ELCC | G26: 0.45 | H26: 0.46 | I26: 0.46 | J26: 0.47 | K26: 0.5 | L26: 2019 | M26: 2500 | N26: 2300 | O26: 2300 | P26: 2300 | Q26: 2200 | R26: 62.5 | S26: 57.5 | T26: 57.5 | U26: 57.5 | V26: 55 | W26: 0.125 | X26: 0.115 | Y26: 0.115 | Z26: 0.115 | AA26: 0.11 | AB26: 35 | AE26: 31.536 | AF26: 0.9 | AL26: ELE | AM26: =A26 -> P-TH-IGCC-COA03 | AN26: =D26 -> PWR Integrated Gasification Combined Cycle coal new | AO26: PJ | AP26: GW | AQ26: DAYNITE | AW26: Integrated Gasification Combined Cycle coal
A27: P-TH-IGCC-PEA03 | B27: ETRI2014 | C27: ETRI2014 | D27: ="PWR "&AW27&" new" -> PWR Integrated Gasification Combined Cycle peat new | E27: PWRPEA | F27: ELCC | G27: 0.43 | H27: 0.45 | I27: 0.46 | J27: 0.47 | K27: 0.47 | L27: 2019 | M27: 3100 | N27: 3000 | O27: 3000 | P27: 3000 | Q27: 3000 | R27: 93 | S27: 90 | T27: 90 | U27: 90 | V27: 90 | W27: 0.217 | X27: 0.21 | Y27: 0.21 | Z27: 0.21 | AA27: 0.21 | AB27: 35 | AE27: 31.536 | AF27: 0.9 | AL27: ELE | AM27: =A27 -> P-TH-IGCC-PEA03 | AN27: =D27 -> PWR Integrated Gasification Combined Cycle peat new | AO27: PJ | AP27: GW | AQ27: DAYNITE | AW27: Integrated Gasification Combined Cycle peat
A28: *P-TH-CCGT-GAS-CCS04 | B28: ETRI2018 | C28: ETRI2014 | D28: ="PWR "&AW28&" new" -> PWR CCGT advanced CCS post combustion new | E28: PWRGAS | F28: ELCC | G28: 0.5 | H28: 0.52 | I28: 0.55 | J28: 0.55 | K28: 0.55 | L28: 2030 | O28: =VLOOKUP($A28,ETRI_Cost!$A:$I,7,FALSE) -> 1390 | P28: =VLOOKUP($A28,ETRI_Cost!$A:$I,8,FALSE) -> 1310 | Q28: =VLOOKUP($A28,ETRI_Cost!$A:$I,9,FALSE) -> 1280 | R28: 37.5 | S28: 37.5 | T28: 37.5 | U28: 37.5 | V28: 37.5 | W28: 0.06 | X28: 0.06 | Y28: 0.06 | Z28: 0.06 | AA28: 0.06 | AB28: 30 | AE28: 31.536 | AF28: 0.9 | AL28: ELE | AM28: =A28 -> *P-TH-CCGT-GAS-CCS04 | AN28: =D28 -> PWR CCGT advanced CCS post combustion new | AO28: PJ | AP28: GW | AQ28: DAYNITE | AW28: CCGT advanced CCS post combustion
A29: *P-TH-SC-COA-CCS04 | B29: ETRI2018 | C29: ETRI2014 | D29: ="PWR "&AW29&" new" -> PWR Pulverised coal supercritical CCS post-combustion new | E29: PWRCOA | F29: ELCC | G29: 0.34 | H29: 0.35 | I29: 0.35 | J29: 0.38 | K29: 0.38 | L29: 2030 | O29: =VLOOKUP($A29,ETRI_Cost!$A:$I,7,FALSE) -> 2740 | P29: =VLOOKUP($A29,ETRI_Cost!$A:$I,8,FALSE) -> 2590 | Q29: =VLOOKUP($A29,ETRI_Cost!$A:$I,9,FALSE) -> 2570 | R29: 75 | S29: 67.5 | T29: 63.75 | U29: 63.75 | V29: 63.75 | W29: 0.165 | X29: 0.1485 | Y29: 0.14025 | Z29: 0.14025 | AA29: 0.14025 | AB29: 40 | AE29: 31.536 | AF29: 0.9 | AL29: ELE | AM29: =A29 -> *P-TH-SC-COA-CCS04 | AN29: =D29 -> PWR Pulverised coal supercritical CCS post-combustion new | AO29: PJ | AP29: GW | AQ29: DAYNITE | AW29: Pulverised coal supercritical CCS post-combustion
A30: *P-TH-FB-PEA-CCS04 | B30: ETRI2014 | C30: ETRI2014 | D30: ="PWR "&AW30&" new" -> PWR Fluidised bed peat CCS post combustion new | E30: PWRPEA | F30: ELCC | G30: 0.31 | H30: 0.32 | I30: 0.34 | J30: 0.34 | K30: 0.34 | L30: 2030 | M30: 3500 | N30: 3500 | O30: 3500 | P30: 3500 | Q30: 3500 | R30: 87.5 | S30: 87.5 | T30: 87.5 | U30: 87.5 | V30: 87.5 | W30: 0.35 | X30: 0.35 | Y30: 0.35 | Z30: 0.35 | AA30: 0.35 | AB30: 40 | AE30: 31.536 | AF30: 0.85 | AL30: ELE | AM30: =A30 -> *P-TH-FB-PEA-CCS04 | AN30: =D30 -> PWR Fluidised bed peat CCS post combustion new | AO30: PJ | AP30: GW | AQ30: DAYNITE | AW30: Fluidised bed peat CCS post combustion
A31: *P-TH-SC-COA-CCS05 | B31: ETRI2018 | C31: ETRI2014 | D31: ="PWR "&AW31&" new" -> PWR Pulverised coal supercritical CCS oxyfuel new | E31: PWRCOA | F31: ELCC | G31: 0.36 | H31: 0.37 | I31: 0.39 | J31: 0.4 | K31: 0.4 | L31: 2030 | O31: =VLOOKUP($A31,ETRI_Cost!$A:$I,7,FALSE) -> 2690 | P31: =VLOOKUP($A31,ETRI_Cost!$A:$I,8,FALSE) -> 2490 | Q31: =VLOOKUP($A31,ETRI_Cost!$A:$I,9,FALSE) -> 2470 | R31: 75 | S31: 67.5 | T31: 63.75 | U31: 63.75 | V31: 63.75 | W31: 0.09 | X31: 0.081 | Y31: 0.0765 | Z31: 0.0765 | AA31: 0.0765 | AB31: 40 | AE31: 31.536 | AF31: 0.9 | AL31: ELE | AM31: =A31 -> *P-TH-SC-COA-CCS05 | AN31: =D31 -> PWR Pulverised coal supercritical CCS oxyfuel new | AO31: PJ | AP31: GW | AQ31: DAYNITE | AW31: Pulverised coal supercritical CCS oxyfuel
A32: *P-TH-IGCC-COA-CCS06 | B32: ETRI2018 | C32: ETRI2014 | D32: ="PWR "&AW32&" new" -> PWR IGCC coal CCS pre-combustion new | E32: PWRCOA | F32: ELCC | G32: 0.35 | H32: 0.37 | I32: 0.4 | J32: 0.41 | K32: 0.44 | L32: 2030 | O32: =VLOOKUP($A32,ETRI_Cost!$A:$I,7,FALSE) -> 2540 | P32: =VLOOKUP($A32,ETRI_Cost!$A:$I,8,FALSE) -> 2220 | Q32: =VLOOKUP($A32,ETRI_Cost!$A:$I,9,FALSE) -> 2180 | R32: 93 | S32: 86.55 | T32: 84.75 | U32: 84.75 | V32: 84.75 | W32: 0.186 | X32: 0.1731 | Y32: 0.1695 | Z32: 0.1695 | AA32: 0.1695 | AB32: 35 | AE32: 31.536 | AF32: 0.9 | AL32: ELE | AM32: =A32 -> *P-TH-IGCC-COA-CCS06 | AN32: =D32 -> PWR IGCC coal CCS pre-combustion new | AO32: PJ | AP32: GW | AQ32: DAYNITE | AW32: IGCC coal CCS pre-combustion
A33: *P-TH-IGCC-PEA-CCS05 | B33: ETRI2018 | C33: ETRI2014 | D33: ="PWR "&AW33&" new" -> PWR IGCC peat CCS pre combustion new | E33: PWRPEA | F33: ELCC | G33: 0.35 | H33: 0.37 | I33: 0.4 | J33: 0.41 | K33: 0.41 | L33: 2030 | O33: =VLOOKUP($A33,ETRI_Cost!$A:$I,7,FALSE) -> 3870 | P33: =VLOOKUP($A33,ETRI_Cost!$A:$I,8,FALSE) -> 3380 | Q33: =VLOOKUP($A33,ETRI_Cost!$A:$I,9,FALSE) -> 3310 | R33: 103.5 | S33: 100.51 | T33: 100.51 | U33: 100.51 | V33: 100.51 | W33: 0.36 | X33: 0.3496 | Y33: 0.3496 | Z33: 0.3496 | AA33: 0.3496 | AB33: 35 | AE33: 31.536 | AF33: 0.9 | AL33: ELE | AM33: =A33 -> *P-TH-IGCC-PEA-CCS05 | AN33: =D33 -> PWR IGCC peat CCS pre combustion new | AO33: PJ | AP33: GW | AQ33: DAYNITE | AW33: IGCC peat CCS pre combustion
A34: P-RNW-FB-BIO01 | B34: ETRI2014 | C34: ETRI2014 | D34: ="PWR "&AW34&" new" -> PWR Biomass grate furnace steam turbine new | E34: PWRBIO | F34: ELCC | G34: 0.34 | H34: 0.35 | I34: 0.36 | J34: 0.38 | K34: 0.38 | L34: 2019 | M34: 2890 | N34: 2620 | O34: 2370 | P34: 2150 | Q34: 1950 | R34: 63.58 | S34: 57.64 | T34: 52.14 | U34: 47.3 | V34: 42.9 | W34: 0.10115 | X34: 0.0917 | Y34: 0.08295 | Z34: 0.07525 | AA34: 0.06825 | AB34: 25 | AE34: 31.536 | AF34: 0.9 | AL34: ELE | AM34: =A34 -> P-RNW-FB-BIO01 | AN34: New Power Plant - Biomass grate furnace steam turbine | AO34: PJ | AP34: GW | AQ34: DAYNITE | AW34: Biomass grate furnace steam turbine
A35: P-RNW-ST-BIO02 | B35: ETRI2014 | C35: ETRI2014 | D35: ="PWR "&AW35&" new" -> PWR Fluidised bed boiler (circulating or bubbling) plus steam turbine new | E35: PWRBIO | F35: ELCC | G35: 0.35 | H35: 0.36 | I35: 0.37 | J35: 0.38 | K35: 0.39 | L35: 2019 | M35: 2960 | N35: 2620 | O35: 2330 | P35: 2060 | Q35: 1830 | R35: 53.28 | S35: 47.16 | T35: 41.94 | U35: 37.08 | V35: 32.94 | W35: 0.11248 | X35: 0.09956 | Y35: 0.08854 | Z35: 0.07828 | AA35: 0.06954 | AB35: 25 | AE35: 31.536 | AF35: 0.9 | AL35: ELE | AM35: =A35 -> P-RNW-ST-BIO02 | AN35: New Power Plant - Fluidised bed boiler (circulating or bubbling) plus steam turbine | AO35: PJ | AP35: GW | AQ35: DAYNITE | AW35: Fluidised bed boiler (circulating or bubbling) plus steam turbine
A36: P-RNW-IGCC-BIO03 | B36: ETRI2014 | C36: ETRI2014 | D36: ="PWR "&AW36&" new" -> PWR Biomass IGCC new | E36: PWRBIO | F36: ELCC | G36: 0.35 | H36: 0.37 | I36: 0.43 | J36: 0.47 | K36: 0.48 | L36: 2019 | M36: 4810 | N36: 3810 | O36: 3140 | P36: 2840 | Q36: 2560 | R36: 105.82 | S36: 83.82 | T36: 69.08 | U36: 62.48 | V36: 56.32 | W36: 0.39442 | X36: 0.31242 | Y36: 0.25748 | Z36: 0.23288 | AA36: 0.20992 | AB36: 25 | AE36: 31.536 | AF36: 0.9 | AL36: ELE | AM36: =A36 -> P-RNW-IGCC-BIO03 | AN36: New Power Plant - Biomass IGCC | AO36: PJ | AP36: GW | AQ36: DAYNITE | AW36: Biomass IGCC
A37: P-RNW-AB-BIO04 | B37: ETRI2018 | C37: ETRI2014 | D37: ="PWR "&AW37&" new" -> PWR Anaerobic digestion new | E37: PWRBIO | F37: ELCC | G37: 0.36 | H37: 0.38 | I37: 0.4 | J37: 0.42 | K37: 0.45 | L37: 2019 | M37: =VLOOKUP($A37,ETRI_Cost!$A:$I,5,FALSE) -> 3100 | N37: =VLOOKUP($A37,ETRI_Cost!$A:$I,6,FALSE) -> 2860 | O37: =VLOOKUP($A37,ETRI_Cost!$A:$I,7,FALSE) -> 2740 | P37: =VLOOKUP($A37,ETRI_Cost!$A:$I,8,FALSE) -> 2630 | Q37: =VLOOKUP($A37,ETRI_Cost!$A:$I,9,FALSE) -> 2510 | R37: 159.08 | S37: 130.38 | T37: 113.16 | U37: 103.32 | V37: 94.3 | W37: 0.12028 | X37: 0.09858 | Y37: 0.08556 | Z37: 0.07812 | AA37: 0.0713 | AB37: 20 | AE37: 31.536 | AF37: 0.9 | AL37: ELE | AM37: =A37 -> P-RNW-AB-BIO04 | AN37: New Power Plant - Anaerobic digestion | AO37: PJ | AP37: GW | AQ37: DAYNITE | AW37: Anaerobic digestion
A38: P-RNW-ST-MSW04 | B38: ETRI2014 | C38: ETRI2014 | D38: ="PWR "&AW38&" new" -> PWR Municipal solid waste incinerator new | E38: PWRMSW | F38: ELCC | G38: 0.27 | H38: 0.31 | I38: 0.34 | J38: 0.37 | K38: 0.42 | L38: 2019 | M38: 6080 | N38: 5630 | O38: 5240 | P38: 4870 | Q38: 4540 | R38: 182.4 | S38: 168.9 | T38: 157.2 | U38: 146.1 | V38: 136.2 | W38: 0.41952 | X38: 0.38847 | Y38: 0.36156 | Z38: 0.33603 | AA38: 0.31326 | AB38: 25 | AE38: 31.536 | AF38: 0.9 | AL38: ELE | AM38: =A38 -> P-RNW-ST-MSW04 | AN38: New Power Plant - Municipal solid waste incinerator | AO38: PJ | AP38: GW | AQ38: DAYNITE | AW38: Municipal solid waste incinerator
A41: Source: UK TIMES (for H2)
D42: ~FI_T: MEUR2012 | AJ42: ~FI_Process
...

Sheet IMPEXP
A2: Electricity Interconnector | G2: ~FI_T: MEUR2014 | S2: ~FI_Process
A3: Region | B3: TechName | C3: *TechDesc | D3: Comm-IN | E3: Comm-OUT | F3: Year | G3: LimType | H3: NCAP_START | I3: NCAP_TLIFE | J3: PRC_CAPACT | K3: COST~2015 | L3: COST~2020 | M3: COST~2030 | N3: COST~2040 | O3: COST~2050 | P3: CAP_BND | Q3: CAP_BND~0 | S3: Sets | T3: Region | U3: TechName | V3: TechDesc | W3: Tact | X3: Tcap | Y3: Tslvl | Z3: PrimaryCG | AA3: Vintage
A4: *Region Name | B4: Technology Name | C4: Technology Description | K4: Euro/GJ | L4: Euro/GJ | M4: Euro/GJ | N4: Euro/GJ | O4: Euro/GJ | P4: GW | Q4: GW | S4: *Process Set Membership | T4: Region Name | U4: Technology Name | V4: Technology Description | W4: Activity Unit | X4: Capacity Unit | Y4: TimeSlice level of Process Activity | Z4: Primary Commodity Group | AA4: Vintage Tracking
A5: =T5 -> IE,National | B5: =U5 -> IMPELC_FR-CI | C5: =V5 -> Import of Electricity - France Celtic Interconnector | E5: ELCC | F5: 2026 | G5: FX | H5: 2026 | I5: 100 | J5: 31.536 | K5: 12.775231 | L5: 13.844655 | M5: 20.699647 | N5: 24.100187 | O5: 27.970361 | P5: 0.7 | Q5: 5 | S5: IMP | T5: IE,National | U5: IMPELC_FR-CI | V5: Import of Electricity - France Celtic Interconnector | W5: PJ | X5: GW | Y5: DAYNITE
A6: =T6 -> IE,National | B6: =U6 -> EXPELC_FR-CI | C6: =V6 -> Export of Electricity - France Celtic Interconnector | D6: ELCC | F6: 2026 | G6: FX | H6: 2026 | I6: 100 | J6: 31.536 | K6: 8.942662 | L6: 9.6912586 | M6: 14.489753 | N6: 16.870131 | O6: 19.579253 | P6: 0.7 | Q6: 5 | S6: EXP | T6: IE,National | U6: EXPELC_FR-CI | V6: Export of Electricity - France Celtic Interconnector | W6: PJ | X6: GW | Y6: DAYNITE
A7: =T7 -> IE,National | B7: =U7 -> IMPELC_UK-GL | C7: =V7 -> Import of Electricity - UK Greenlink | E7: ELCC | F7: 2024 | G7: FX | H7: 2024 | I7: 100 | J7: 31.536 | K7: 12.775231 | L7: 13.844655 | M7: 20.699647 | N7: 24.100187 | O7: 27.970361 | P7: 0.5 | Q7: 5 | S7: IMP | T7: IE,National | U7: IMPELC_UK-GL | V7: Import of Electricity - UK Greenlink | W7: PJ | X7: GW | Y7: DAYNITE
A8: =T8 -> IE,National | B8: =U8 -> EXPELC_UK-GL | C8: =V8 -> Export of Electricity - UK Greenlink | D8: ELCC | F8: 2024 | G8: FX | H8: 2024 | I8: 100 | J8: 31.536 | K8: 8.942662 | L8: 9.6912586 | M8: 14.489753 | N8: 16.870131 | O8: 19.579253 | P8: 0.5 | Q8: 5 | S8: EXP | T8: IE,National | U8: EXPELC_UK-GL | V8: Export of Electricity - UK Greenlink | W8: PJ | X8: GW | Y8: DAYNITE

Sheet ELC_WIN
D1: ~FI_T: MEUR2024 | AJ1: ~FI_Process
A2: TechName | B2: *TechDesc | C2: Comm-IN | D2: Comm-OUT | E2: EFF | F2: EFF~2020 | G2: EFF~2030 | H2: EFF~2040 | I2: EFF~2050 | J2: Start | K2: INVCOST | L2: INVCOST~2025 | M2: INVCOST~2030 | N2: INVCOST~2040 | O2: INVCOST~2050 | P2: FIXOM~2025 | Q2: FIXOM~2020 | R2: FIXOM~2030 | S2: FIXOM~2040 | T2: FIXOM~2050 | U2: VAROM | V2: VAROM~2020 | W2: VAROM~2030 | X2: VAROM~2040 | Y2: VAROM~2050 | Z2: LIFE | AA2: LIFE~2020 | AB2: LIFE~2030 | AC2: Cap2Act | AD2: AFA | AE2: AFA~2020 | AF2: AFA~2030 | AG2: AFA~2040 | AH2: AFA~2050 | AJ2: Sets | AK2: TechName | AL2: TechDesc | AM2: Tact | AN2: Tcap | AO2: Tslvl | AP2: PrimaryCG | AQ2: Vintage
A3: *Technology Name | B3: Technology Description | C3: Input Commodity | D3: Output Commodity | E3: Efficiency | K3: CAPEX REF (€2013/kW) | P3: FOM (€2013/kW) | U3: VOM (€2013/GJ) | Z3: Technical life | AD3: Max. capacity factor | AJ3: *Process Set Membership | AK3: Technology Name | AL3: Technology Description | AM3: Activity Unit | AN3: Capacity Unit | AO3: TimeSlice Level | AP3: Primary CommGrp | AQ3: Vintage Tracking
A4: P-RNW-WIN-ON01 | B4: New Power Plant - Onshore Wind - Connection Cost Level 01 | C4: PWRWIN | D4: ELCC | E4: 1 | J4: 2019 | L4: 1526 | O4: 1317 | P4: 37.8 | T4: =P4*O4/L4 -> 32.622936 | Z4: 20 | AA4: 22 | AB4: 25 | AC4: 31.536 | AJ4: ELE | AK4: P-RNW-WIN-ON01 | AL4: New Power Plant - Onshore Wind - Connection Cost Level 01 | AM4: PJ | AN4: GW | AO4: DAYNITE
A5: P-RNW-WIN-ON02 | B5: New Power Plant - Onshore Wind - Connection Cost Level 02 | C5: PWRWIN | D5: ELCC | E5: 1 | J5: 2019 | L5: 1575 | O5: 1366 | P5: 37.8 | T5: =P5*O5/L5 -> 32.784 | Z5: 20 | AA5: 22 | AB5: 25 | AC5: 31.536 | AJ5: ELE | AK5: P-RNW-WIN-ON02 | AL5: New Power Plant - Onshore Wind - Connection Cost Level 02 | AM5: PJ | AN5: GW | AO5: DAYNITE
A6: P-RNW-WIN-ON03 | B6: New Power Plant - Onshore Wind - Connection Cost Level 03 | C6: PWRWIN | D6: ELCC | E6: 1 | J6: 2019 | L6: 1662 | O6: 1451 | P6: 37.8 | T6: =P6*O6/L6 -> 33.001083 | Z6: 20 | AA6: 22 | AB6: 25 | AC6: 31.536 | AJ6: ELE | AK6: P-RNW-WIN-ON03 | AL6: New Power Plant - Onshore Wind - Connection Cost Level 03 | AM6: PJ | AN6: GW | AO6: DAYNITE
A7: P-RNW-WIN-ON04 | B7: New Power Plant - Onshore Wind - Connection Cost Level 04 | C7: PWRWIN | D7: ELCC | E7: 1 | J7: 2019 | L7: 1853 | O7: 1641 | P7: 37.8 | T7: =P7*O7/L7 -> 33.475337 | Z7: 20 | AA7: 22 | AB7: 25 | AC7: 31.536 | AJ7: ELE | AK7: P-RNW-WIN-ON04 | AL7: New Power Plant - Onshore Wind - Connection Cost Level 04 | AM7: PJ | AN7: GW | AO7: DAYNITE
A8: P-RNW-WIN-ON05 | B8: New Power Plant - Onshore Wind - Connection Cost Level 05 | C8: PWRWIN | D8: ELCC | E8: 1 | J8: 2019 | L8: 2303 | O8: 2088 | P8: 37.8 | T8: =P8*O8/L8 -> 34.271125 | Z8: 20 | AA8: 22 | AB8: 25 | AC8: 31.536 | AJ8: ELE | AK8: P-RNW-WIN-ON05 | AL8: New Power Plant - Onshore Wind - Connection Cost Level 05 | AM8: PJ | AN8: GW | AO8: DAYNITE
A9: P-RNW-WIN-OF02 | B9: PWR Offshore wind new | C9: PWRWIN | D9: ELCC | E9: 1 | J9: 2019 | L9: =3118 -> 3118 | O9: 2827 | P9: 128.39 | Q9: =+P9 -> 128.39 | T9: =+Q9*O9/L9 -> 116.40748 | Z9: 20 | AA9: 25 | AB9: 30 | AC9: 31.536

Sheet WIN_ON_COST
A1: fid | B1: Merged_ID | C1: Parcel | D1: COUNTY - 1 | E1: COUNTY - 2 | F1: Station ID | G1: name | H1: operator | I1: voltage | J1: voltage_pr | K1: voltage_te | L1: Distance | M1: Round Up Distance | N1: Area_km_2_ | O1: Class | P1: Area With Packing Density Applied(km2) | Q1: Rationalised Output Per Parcel (MW) | R1: Rationalised Output Per Parcel (MW) | S1: Cost (€) | T1: PS | U1: Cost Per MW | V1: Watt per Euro | AG1: Investment Cost
A2: 1 | B2: 1 | C2: CL1-001 | D2: KERRY | E2: KERRY | F2: SS-636 | G2: Garranebane 38kV Substation | H2: ESB Networks | I2: 38000 | J2: 38000 | K2: 20000 | L2: 15.861 | M2: 16 | N2: 0.122 | O2: 1 | P2: 0.122 | Q2: 3.45 | R2: 3.45 | S2: 1703340 | T2: 1 | U2: 493721.74 | V2: 2.0254324 | X2: Rationalised Output Per Parcel (MW) | Y2: Connection Cost Million E/Kw | AG2: 2015 | AH2: 2020 | AI2: 2030 | AJ2: 2040 | AK2: 2050
A3: 2 | B3: 2 | C3: CL1-002 | D3: KERRY | E3: KERRY | F3: SS-636 | G3: Garranebane 38kV Substation | H3: ESB Networks | I3: 38000 | J3: 38000 | K3: 20000 | L3: 5.42 | M3: 6 | N3: 0.263 | O3: 1 | P3: 0.263 | Q3: 3.45 | R3: 3.45 | S3: 769410 | T3: 4 | U3: 223017.39 | V3: 4.4839552 | X3: 3.45 | Y3: 493.72174 | AA3: Capacity | AB3: Total Connection Cost | AC3: Cost Range | AE3: Connection Cost (Euro/kW) | AG3: =ETRI_Cost!E43 -> 1350 | AH3: =ETRI_Cost!F45 -> 1290 | AI3: =ETRI_Cost!G45 -> 1190 | AJ3: =ETRI_Cost!H45 -> 1140 | AK3: =ETRI_Cost!I45 -> 1110
A4: 3 | B4: 3 | C4: CL1-003 | D4: GALWAY | E4: GALWAY | F4: SS-106 | G4: Clifden 38kV Substation | H4: ESB Networks | I4: 38000 | J4: 38000 | K4: low | L4: 11.691 | M4: 12 | N4: 0.133 | O4: 1 | P4: 0.133 | Q4: 3.45 | R4: 3.45 | S4: 1492540 | T4: 1 | U4: 432620.29 | V4: 2.3114958 | X4: 3.45 | Y4: 223.01739 | AA4: =SUMIFS(X:X,Y:Y,">"&AC4,Y:Y,"<"&AD4)/1000 -> 8.1111 | AB4: {=SUMPRODUCT(X:X,Y:Y,--(Y:Y>AC4),--(Y:Y<AD4))} -> 199028.83 | AC4: 0 | AD4: 30 | AE4: {=SUMPRODUCT(X:X,Y:Y,--(Y:Y>AC4),--(Y:Y<AD4))/SUMIFS(X:X,Y:Y,">"&AC4,Y:Y,"<"&AD4)} -> 24.537835 | AG4: =AG3+$AE4 -> 1374.5378 | AH4: =AH3+$AE4 -> 1314.5378 | AI4: =AI3+$AE4 -> 1214.5378 | AJ4: =AJ3+$AE4 -> 1164.5378 | AK4: =AK3+$AE4 -> 1134.5378
A5: 4 | B5: 4 | C5: CL1-004 | D5: DONEGAL | E5: DONEGAL | F5: SS-250 | G5: Kilcar 38kV Substation | H5: ESB Networks | I5: 38000 | J5: 38000 | K5: 10000 | L5: 13.24 | M5: 14 | N5: 0.133 | O5: 1 | P5: 0.133 | Q5: 3.45 | R5: 3.45 | S5: 1597940 | T5: 1 | U5: 463171.01 | V5: 2.1590298 | X5: 3.45 | Y5: 432.62029 | AA5: =SUMIFS(X:X,Y:Y,">"&AC5,Y:Y,"<"&AD5)/1000 -> 8.73225 | AB5: {=SUMPRODUCT(X:X,Y:Y,--(Y:Y>AC5),--(Y:Y<AD5))} -> 338735.64 | AC5: 30 | AD5: 50 | AE5: {=SUMPRODUCT(X:X,Y:Y,--(Y:Y>AC5),--(Y:Y<AD5))/SUMIFS(X:X,Y:Y,">"&AC5,Y:Y,"<"&AD5)} -> 38.791336 | AG5: =AG4+$AE5 -> 1413.3292 | AH5: =AH4+$AE5 -> 1353.3292 | AI5: =AI4+$AE5 -> 1253.3292 | AJ5: =AJ4+$AE5 -> 1203.3292 | AK5: =AK4+$AE5 -> 1173.3292
A6: 5 | B6: 5 | C6: CL1-005 | D6: DONEGAL | E6: DONEGAL | F6: SS-138 | G6: Creeslough 38kV Substation | H6: ESB Networks | I6: 38000 | J6: 38000 | K6: low | L6: 9.962 | M6: 10 | N6: 0.157 | O6: 1 | P6: 0.157 | Q6: 3.45 | R6: 3.45 | S6: 1387140 | T6: 1 | U6: 402069.57 | V6: 2.4871318 | X6: 3.45 | Y6: 463.17101 | AA6: =SUMIFS(X:X,Y:Y,">"&AC6,Y:Y,"<"&AD6)/1000 -> 5.7897 | AB6: {=SUMPRODUCT(X:X,Y:Y,--(Y:Y>AC6),--(Y:Y<AD6))} -> 399230.19 | AC6: 50 | AD6: 100 | AE6: {=SUMPRODUCT(X:X,Y:Y,--(Y:Y>AC6),--(Y:Y<AD6))/SUMIFS(X:X,Y:Y,">"&AC6,Y:Y,"<"&AD6)} -> 68.955246 | AG6: =AG5+$AE6 -> 1482.2844 | AH6: =AH5+$AE6 -> 1422.2844 | AI6: =AI5+$AE6 -> 1322.2844 | AJ6: =AJ5+$AE6 -> 1272.2844 | AK6: =AK5+$AE6 -> 1242.2844
A7: 6 | B7: 6 | C7: CL1-006 | D7: DONEGAL | E7: DONEGAL | F7: SS-119 | G7: Drumlough Hill (1) 38kV Substation | H7: ESB Networks | I7: 38000 | J7: low | K7: 38000 | L7: 10.639 | M7: 11 | N7: 0.093 | O7: 1 | P7: 0.093 | Q7: 3.45 | R7: 3.45 | S7: 1439840 | T7: 1 | U7: 417344.93 | V7: 2.3960996 | X7: 3.45 | Y7: 402.06957 | AA7: =SUMIFS(X:X,Y:Y,">"&AC7,Y:Y,"<"&AD7)/1000 -> 3.9777 | AB7: {=SUMPRODUCT(X:X,Y:Y,--(Y:Y>AC7),--(Y:Y<AD7))} -> 606529.79 | AC7: 100 | AD7: 200 | AE7: {=SUMPRODUCT(X:X,Y:Y,--(Y:Y>AC7),--(Y:Y<AD7))/SUMIFS(X:X,Y:Y,">"&AC7,Y:Y,"<"&AD7)} -> 152.48254 | AG7: =AG6+$AE7 -> 1634.767 | AH7: =AH6+$AE7 -> 1574.767 | AI7: =AI6+$AE7 -> 1474.767 | AJ7: =AJ6+$AE7 -> 1424.767 | AK7: =AK6+$AE7 -> 1394.767
A8: 7 | B8: 7 | C8: CL1-007 | D8: CLARE | E8: CLARE | F8: SS-708 | H8: EirGrid | I8: 110000 | J8: medium | K8: 110000 | L8: 1.526 | M8: 2 | N8: 0.126 | O8: 1 | P8: 0.126 | Q8: 3.45 | R8: 3.45 | S8: 1340080 | T8: 11 | U8: 388428.99 | V8: 2.5744732 | X8: 3.45 | Y8: 417.34493 | AA8: =SUMIFS(X:X,Y:Y,">"&AC8,Y:Y,"<"&AD8)/1000 -> 3.99075 | AB8: {=SUMPRODUCT(X:X,Y:Y,--(Y:Y>AC8),--(Y:Y<AD8))} -> 1427308.2 | AC8: 200 | AD8: 1000 | AE8: {=SUMPRODUCT(X:X,Y:Y,--(Y:Y>AC8),--(Y:Y<AD8))/SUMIFS(X:X,Y:Y,">"&AC8,Y:Y,"<"&AD8)} -> 357.65413 | AG8: =AG7+$AE8 -> 1992.4211 | AH8: =AH7+$AE8 -> 1932.4211 | AI8: =AI7+$AE8 -> 1832.4211 | AJ8: =AJ7+$AE8 -> 1782.4211 | AK8: =AK7+$AE8 -> 1752.4211
A9: 8 | B9: 8 | C9: CL1-008 | D9: DUBLIN | E9: DUBLIN | F9: SS-014 | G9: Ballyboden 38kV Substation | H9: ESB Networks | I9: 38000 | J9: 38000 | K9: 10000 | L9: 6.009 | M9: 7 | N9: 0.28 | O9: 1 | P9: 0.28 | Q9: 3.45 | R9: 3.45 | S9: 839680 | T9: 4 | U9: 243385.51 | V9: 4.1087081 | X9: 3.45 | Y9: 388.42899
A10: 9 | B10: 9 | C10: CL1-009 | D10: DUBLIN | E10: DUBLIN | F10: SS-014 | G10: Ballyboden 38kV Substation | H10: ESB Networks | I10: 38000 | J10: 38000 | K10: 10000 | L10: 5.282 | M10: 6 | N10: 0.178 | O10: 1 | P10: 0.178 | Q10: 3.45 | R10: 3.45 | S10: 769410 | T10: 4 | U10: 223017.39 | V10: 4.4839552 | X10: 3.45 | Y10: 243.38551
A11: 10 | B11: 10 | C11: CL1-010 | D11: WICKLOW | E11: WICKLOW | F11: SS-010 | G11: Fassaroe 110kV Substation | H11: EirGrid | I11: 110000 | J11: 110000 | K11: 38000 | L11: 4.695 | M11: 5 | N11: 0.2 | O11: 1 | P11: 0.2 | Q11: 3.45 | R11: 3.45 | S11: 1679970 | T11: 7 | U11: 486947.83 | V11: 2.0536081 | X11: 3.45 | Y11: 223.01739
A12: 11 | B12: 11 | C12: CL1-011 | D12: WICKLOW | E12: WICKLOW | F12: SS-010 | G12: Fassaroe 110kV Substation | H12: EirGrid | I12: 110000 | J12: 110000 | K12: 38000 | L12: 5.608 | M12: 6 | N12: 0.116 | O12: 1 | P12: 0.116 | Q12: 3.45 | R12: 3.45 | S12: 1732670 | T12: 7 | U12: 502223.19 | V12: 1.9911466 | X12: 3.45 | Y12: 486.94783
A13: 12 | B13: 12 | C13: CL1-012 | D13: WICKLOW | E13: WICKLOW | F13: SS-597 | G13: Kilmartin 38kV Substation | H13: ESB Networks | I13: 38000 | J13: 38000 | K13: low | L13: 5.924 | M13: 6 | N13: 0.134 | O13: 1 | P13: 0.134 | Q13: 3.45 | R13: 3.45 | S13: 769410 | T13: 4 | U13: 223017.39 | V13: 4.4839552 | X13: 3.45 | Y13: 502.22319
A14: 13 | B14: 13 | C14: CL1-013 | D14: CORK | E14: CORK | F14: SS-253 | G14: Ballydehob 38kV Substation | H14: ESB Networks | I14: 38000 | J14: 38000 | K14: low | L14: 8.843 | M14: 9 | N14: 0.139 | O14: 1 | P14: 0.139 | Q14: 3.45 | R14: 3.45 | S14: 1334440 | T14: 1 | U14: 386794.2 | V14: 2.5853542 | X14: 3.45 | Y14: 223.01739
A15: 14 | B15: 14 | C15: CL1-014 | D15: WICKLOW | E15: WICKLOW | F15: SS-037 | G15: Ballybeg 110kV Substation | H15: EirGrid | I15: 110000 | J15: 110000 | K15: 38000 | L15: 4.542 | M15: 5 | N15: 0.154 | O15: 1 | P15: 0.154 | Q15: 3.45 | R15: 3.45 | S15: 1679970 | T15: 7 | U15: 486947.83 | V15: 2.0536081 | X15: 3.45 | Y15: 386.7942
A16: 15 | B16: 15 | C16: CL1-015 | D16: KERRY | E16: KERRY | F16: SS-635 | G16: Dingle 38kV Substation | H16: ESB Networks | I16: 38000 | J16: 38000 | K16: 20000 | L16: 11.995 | M16: 12 | N16: 0.155 | O16: 1 | P16: 0.155 | Q16: 3.45 | R16: 3.45 | S16: 1492540 | T16: 1 | U16: 432620.29 | V16: 2.3114958 | X16: 3.45 | Y16: 486.94783
A17: 16 | B17: 16 | C17: CL1-016 | D17: CORK | E17: CORK | F17: SS-273 | G17: Castletownbere 38kV Substation | H17: ESB Networks | I17: 38000 | J17: 38000 | K17: 20000 | L17: 11.179 | M17: 12 | N17: 0.101 | O17: 1 | P17: 0.101 | Q17: 3.45 | R17: 3.45 | S17: 1492540 | T17: 1 | U17: 432620.29 | V17: 2.3114958 | X17: 3.45 | Y17: 432.62029
A18: 17 | B18: 17 | C18: CL1-017 | D18: DONEGAL | E18: DONEGAL | F18: SS-610 | G18: Milford (North) 38kV Substation | H18: ESB Networks | I18: 38000 | J18: 38000 | K18: low | L18: 14.864 | M18: 15 | N18: 0.149 | O18: 1 | P18: 0.149 | Q18: 3.45 | R18: 3.45 | S18: 1650640 | T18: 1 | U18: 478446.38 | V18: 2.0900984 | X18: 3.45 | Y18: 432.62029
A19: 18 | B19: 18 | C19: CL1-018 | D19: DONEGAL | E19: DONEGAL | F19: SS-117 | G19: Crockahenny 38kV Substation | H19: ESB Networks | I19: 38000 | J19: low | K19: 38000 | L19: 2.217 | M19: 3 | N19: 0.259 | O19: 1 | P19: 0.259 | Q19: 3.45 | R19: 3.45 | S19: 558600 | T19: 4 | U19: 161913.04 | V19: 6.1761547 | X19: 3.45 | Y19: 478.44638
A20: 19 | B20: 19 | C20: CL1-019 | D20: MAYO | E20: MAYO | F20: SS-642 | G20: Achill 38kV Substation | H20: ESB Networks | I20: 38000 | J20: 38000 | K20: 20000 | L20: 7.887 | M20: 8 | N20: 0.337 | O20: 1 | P20: 0.337 | Q20: 3.45 | R20: 3.45 | S20: 909950 | T20: 4 | U20: 263753.62 | V20: 3.7914171 | X20: 3.45 | Y20: 161.91304
A21: 20 | B21: 20 | C21: CL1-020 | D21: DONEGAL | E21: DONEGAL | F21: SS-123 | G21: Derrybeg 38kV Substation | H21: ESB Networks | I21: 38000 | J21: 38000 | K21: 10000 | L21: 8.548 | M21: 9 | N21: 0.523 | O21: 1 | P21: 0.523 | Q21: 3.45 | R21: 3.45 | S21: 1334440 | T21: 1 | U21: 386794.2 | V21: 2.5853542 | X21: 3.45 | Y21: 263.75362
A22: 21 | B22: 21 | C22: CL1-021 | D22: KERRY | E22: KERRY | F22: SS-636 | G22: Garranebane 38kV Substation | H22: ESB Networks | I22: 38000 | J22: 38000 | K22: 20000 | L22: 13.635 | M22: 14 | N22: 0.289 | O22: 1 | P22: 0.289 | Q22: 3.45 | R22: 3.45 | S22: 1597940 | T22: 1 | U22: 463171.01 | V22: 2.1590298 | X22: 3.45 | Y22: 386.7942
A23: 22 | B23: 22 | C23: CL1-022 | D23: WICKLOW | E23: WICKLOW | F23: SS-209 | G23: Blessington 38kV Substation | H23: ESB Networks | I23: 38000 | J23: 38000 | K23: 20000 | L23: 7.06 | M23: 8 | N23: 0.325 | O23: 1 | P23: 0.325 | Q23: 3.45 | R23: 3.45 | S23: 909950 | T23: 4 | U23: 263753.62 | V23: 3.7914171 | X23: 3.45 | Y23: 463.17101
A24: 23 | B24: 23 | C24: CL1-023 | D24: DONEGAL | E24: DONEGAL | F24: SS-117 | G24: Crockahenny 38kV Substation | H24: ESB Networks | I24: 38000 | J24: low | K24: 38000 | L24: 4.876 | M24: 5 | N24: 0.614 | O24: 1 | P24: 0.4605 | Q24: 3.45 | R24: 3.45 | S24: 699140 | T24: 4 | U24: 202649.28 | V24: 4.934634 | X24: 3.45 | Y24: 263.75362
A25: 24 | B25: 24 | C25: CL1-024 | D25: DONEGAL | E25: DONEGAL | F25: SS-617 | G25: Mulreavy 110kV Substation | H25: EirGrid | I25: 110000 | J25: 33000 | K25: 110000 | L25: 12.664 | M25: 13 | N25: 0.209 | O25: 1 | P25: 0.209 | Q25: 3.45 | R25: 3.45 | S25: 2101570 | T25: 7 | U25: 609150.72 | V25: 1.6416298 | X25: 3.45 | Y25: 202.64928
A26: 25 | B26: 25 | C26: CL1-025 | D26: CAVAN | E26: CAVAN | F26: SS-110 | G26: Corraclassy 110kV Substation | H26: EirGrid | I26: 110000 | L26: 10.905 | M26: 11 | N26: 0.786 | O26: 1 | P26: 0.5895 | Q26: 3.45 | R26: 3.45 | S26: 1996170 | T26: 7 | U26: 578600 | V26: 1.7283097 | X26: 3.45 | Y26: 609.15072
A27: 26 | B27: 26 | C27: CL1-026 | D27: LOUTH | E27: LOUTH | F27: SS-650 | G27: Ballymascanlan 38kV Substation | H27: ESB Networks | I27: 38000 | J27: 38000 | K27: low | L27: 4.994 | M27: 5 | N27: 0.211 | O27: 1 | P27: 0.211 | Q27: 3.45 | R27: 3.45 | S27: 699140 | T27: 4 | U27: 202649.28 | V27: 4.934634 | X27: 3.45 | Y27: 578.6
A28: 27 | B28: 27 | C28: CL1-027 | D28: CORK | E28: CORK | F28: SS-362 | G28: Glengarriff 38kV Substation | H28: ESB Networks | I28: 38000 | J28: 38000 | K28: 20000 | L28: 12.641 | M28: 13 | N28: 0.281 | O28: 1 | P28: 0.281 | Q28: 3.45 | R28: 3.45 | S28: 1545240 | T28: 1 | U28: 447895.65 | V28: 2.2326629 | X28: 3.45 | Y28: 202.64928
A29: 28 | B29: 28 | C29: CL1-028 | D29: KERRY | E29: KERRY | F29: SS-362 | G29: Glengarriff 38kV Substation | H29: ESB Networks | I29: 38000 | J29: 38000 | K29: 20000 | L29: 12.848 | M29: 13 | N29: 0.134 | O29: 1 | P29: 0.134 | Q29: 3.45 | R29: 3.45 | S29: 1545240 | T29: 1 | U29: 447895.65 | V29: 2.2326629 | X29: 3.45 | Y29: 447.89565
A30: 29 | B30: 29 | C30: CL1-029 | D30: CORK | E30: CORK | F30: SS-273 | G30: Castletownbere 38kV Substation | H30: ESB Networks | I30: 38000 | J30: 38000 | K30: 20000 | L30: 12.044 | M30: 13 | N30: 0.17 | O30: 1 | P30: 0.17 | Q30: 3.45 | R30: 3.45 | S30: 1545240 | T30: 1 | U30: 447895.65 | V30: 2.2326629 | X30: 3.45 | Y30: 447.89565
A31: 30 | B31: 30 | C31: CL1-030 | D31: KERRY | E31: KERRY | F31: SS-337 | G31: Knockaneden 38kV Substation | H31: ESB Networks | I31: 38000 | J31: low | K31: 38000 | L31: 13.637 | M31: 14 | N31: 0.496 | O31: 1 | P31: 0.496 | Q31: 3.45 | R31: 3.45 | S31: 1597940 | T31: 1 | U31: 463171.01 | V31: 2.1590298 | X31: 3.45 | Y31: 447.89565
A32: 31 | B32: 31 | C32: CL1-031 | D32: KERRY | E32: KERRY | F32: SS-151 | G32: Kenmare 38kV Substation | H32: ESB Networks | I32: 38000 | J32: 38000 | K32: low | L32: 12.786 | M32: 13 | N32: 0.351 | O32: 1 | P32: 0.351 | Q32: 3.45 | R32: 3.45 | S32: 1545240 | T32: 1 | U32: 447895.65 | V32: 2.2326629 | X32: 3.45 | Y32: 463.17101
A33: 32 | B33: 32 | C33: CL1-032 | D33: KERRY | E33: KERRY | F33: SS-151 | G33: Kenmare 38kV Substation | H33: ESB Networks | I33: 38000 | J33: 38000 | K33: low | L33: 14.48 | M33: 15 | N33: 0.438 | O33: 1 | P33: 0.438 | Q33: 3.45 | R33: 3.45 | S33: 1650640 | T33: 1 | U33: 478446.38 | V33: 2.0900984 | X33: 3.45 | Y33: 447.89565
A34: 33 | B34: 33 | C34: CL1-033 | D34: KERRY | E34: KERRY | F34: SS-321 | G34: Milltown 38kV Substation | H34: ESB Networks | I34: 38000 | J34: 38000 | K34: 20000 | L34: 11.713 | M34: 12 | N34: 0.121 | O34: 1 | P34: 0.121 | Q34: 3.45 | R34: 3.45 | S34: 1492540 | T34: 1 | U34: 432620.29 | V34: 2.3114958 | X34: 3.45 | Y34: 478.44638
A35: 34 | B35: 34 | C35: CL1-034 | D35: KERRY | E35: KERRY | F35: SS-387 | G35: Coolcorcoran 38kV Substation | H35: ESB Networks | I35: 38000 | J35: 38000 | K35: low | L35: 11.301 | M35: 12 | N35: 0.237 | O35: 1 | P35: 0.237 | Q35: 3.45 | R35: 3.45 | S35: 1492540 | T35: 1 | U35: 432620.29 | V35: 2.3114958 | X35: 3.45 | Y35: 432.62029
A36: 35 | B36: 35 | C36: CL1-035 | D36: KERRY | E36: KERRY | F36: SS-151 | G36: Kenmare 38kV Substation | H36: ESB Networks | I36: 38000 | J36: 38000 | K36: low | L36: 15.65 | M36: 16 | N36: 0.262 | O36: 1 | P36: 0.262 | Q36: 3.45 | R36: 3.45 | S36: 1703340 | T36: 1 | U36: 493721.74 | V36: 2.0254324 | X36: 3.45 | Y36: 432.62029
A37: 36 | B37: 36 | C37: CL1-036 | D37: KERRY | E37: KERRY | F37: SS-636 | G37: Garranebane 38kV Substation | H37: ESB Networks | I37: 38000 | J37: 38000 | K37: 20000 | L37: 4.091 | M37: 5 | N37: 0.567 | O37: 1 | P37: 0.567 | Q37: 3.45 | R37: 3.45 | S37: 699140 | T37: 4 | U37: 202649.28 | V37: 4.934634 | X37: 3.45 | Y37: 493.72174
A38: 37 | B38: 37 | C38: CL1-037 | D38: KERRY | E38: KERRY | F38: SS-337 | G38: Knockaneden 38kV Substation | H38: ESB Networks | I38: 38000 | J38: low | K38: 38000 | L38: 2.79 | M38: 3 | N38: 0.399 | O38: 1 | P38: 0.399 | Q38: 3.45 | R38: 3.45 | S38: 558600 | T38: 4 | U38: 161913.04 | V38: 6.1761547 | X38: 3.45 | Y38: 202.64928
A39: 38 | B39: 38 | C39: CL1-038 | D39: KERRY | E39: KERRY | F39: SS-337 | G39: Knockaneden 38kV Substation | H39: ESB Networks | I39: 38000 | J39: low | K39: 38000 | L39: 14.268 | M39: 15 | N39: 0.109 | O39: 1 | P39: 0.109 | Q39: 3.45 | R39: 3.45 | S39: 1650640 | T39: 1 | U39: 478446.38 | V39: 2.0900984 | X39: 3.45 | Y39: 161.91304
A40: 39 | B40: 39 | C40: CL1-039 | D40: KERRY | E40: KERRY | F40: SS-337 | G40: Knockaneden 38kV Substation | H40: ESB Networks | I40: 38000 | J40: low | K40: 38000 | L40: 9.745 | M40: 10 | N40: 0.123 | O40: 1 | P40: 0.123 | Q40: 3.45 | R40: 3.45 | S40: 1387140 | T40: 1 | U40: 402069.57 | V40: 2.4871318 | X40: 3.45 | Y40: 478.44638
...

Sheet ELC_CCS
B1: Electricity Generators Database - CCS options
B2: Sources:
B3: Techno-economic data: ETRI 2014 (https://setis.ec.europa.eu/publications/jrc-setis-reports/etri-2014 )
B4: Process options: Irish TIMES v1.0 (using Fionn's analysis)
E6: ~FI_T: MEUR2015 | AO6: ~FI_Process | AX6: ~FI_Comm
B7: TechName | C7: *TechDesc | D7: Comm-IN | E7: Comm-OUT | F7: EFF | G7: EFF~2020 | H7: EFF~2030 | I7: EFF~2040 | J7: EFF~2050 | K7: Start | L7: INVCOST | M7: INVCOST~2020 | N7: INVCOST~2030 | O7: INVCOST~2040 | P7: INVCOST~2050 | Q7: FIXOM | R7: FIXOM~2020 | S7: FIXOM~2030 | T7: FIXOM~2040 | U7: FIXOM~2050 | V7: VAROM | W7: VAROM~2020 | X7: VAROM~2030 | Y7: VAROM~2040 | Z7: VAROM~2050 | AA7: *INVCOST | AB7: *INVCOST | AC7: *VAROM | AD7: *VAROM | AE7: LIFE | AF7: Cap2Act | AG7: AFA | AH7: AFA~2020 | AI7: AFA~2030 | AJ7: AFA~2040 | AK7: AFA~2050 | AO7: Sets | AP7: TechName | AQ7: TechDesc | AR7: Tact | AS7: Tcap | AT7: Tslvl | AU7: PrimaryCG | AV7: Vintage | AX7: Csets | AY7: CommName | AZ7: CommDesc | BA7: Unit | BB7: LimType | BC7: CTSLvl | BD7: PeakTS | BE7: Ctype
B8: *Technology Name | C8: Technology Description | D8: Input Commodity | E8: Output Commodity | F8: Efficiency | L8: Overall CAPEX (€2013/kW) | Q8: FOM (€2013/kW) | V8: Overall VOM (€2013/GJ) | AA8: Pipeline | AB8: Storage | AC8: Pipeline | AD8: Storage | AE8: Technical life | AG8: Max. capacity factor | AO8: \I: Process Set Membership | AP8: Technology Name | AQ8: Technology Description | AR8: Activity Unit | AS8: Capacity Unit | AT8: Timeslice Operational Level | AU8: Operational Commodity Group | AV8: Vintage Tracking | AX8: *Commodity Set Membership | AY8: Commodity Name | AZ8: Commodity Description | BA8: Unit | BB8: Balance Equ Type Override | BC8: Timeslice Tracking Level | BD8: Peak Monitoring | BE8: Electricity Indicator
B9: P-TH-SC-COA-CCS04-MP1 | C9: ="New Power Plant - "&BG9 -> New Power Plant - Pulverised coal supercritical CCS post-combustion_Moneypoint Kinsale | D9: PWRCOA | E9: ="ELCC, "&$AY$9 -> ELCC, PWRCO2S | F9: =IF(ELC_EGP!G$29="","",ELC_EGP!G$29) -> 0.34 | G9: =IF(ELC_EGP!H$29="","",ELC_EGP!H$29) -> 0.35 | H9: =IF(ELC_EGP!I$29="","",ELC_EGP!I$29) -> 0.35 | I9: =IF(ELC_EGP!J$29="","",ELC_EGP!J$29) -> 0.38 | J9: =IF(ELC_EGP!K$29="","",ELC_EGP!K$29) -> 0.38 | K9: =IF(ELC_EGP!L$29="","",ELC_EGP!L$29) -> 2030 | N9: =IF(ELC_EGP!O$29="","",ELC_EGP!O$29)+SUM($AA9:$AB9) -> 3102.3219 | O9: =IF(ELC_EGP!P$29="","",ELC_EGP!P$29)+SUM($AA9:$AB9) -> 2952.3219 | P9: =IF(ELC_EGP!Q$29="","",ELC_EGP!Q$29)+SUM($AA9:$AB9) -> 2932.3219 | Q9: =IF(ELC_EGP!R$29="","",ELC_EGP!R$29) -> 75 | R9: =IF(ELC_EGP!S$29="","",ELC_EGP!S$29) -> 67.5 | S9: =IF(ELC_EGP!T$29="","",ELC_EGP!T$29) -> 63.75 | T9: =IF(ELC_EGP!U$29="","",ELC_EGP!U$29) -> 63.75 | U9: =IF(ELC_EGP!V$29="","",ELC_EGP!V$29) -> 63.75 | V9: =IF(ELC_EGP!W$29="","",ELC_EGP!W$29)+SUM($AC9:$AD9) -> 0.87577648 | W9: =IF(ELC_EGP!X$29="","",ELC_EGP!X$29)+SUM($AC9:$AD9) -> 0.85927648 | X9: =IF(ELC_EGP!Y$29="","",ELC_EGP!Y$29)+SUM($AC9:$AD9) -> 0.85102648 | Y9: =IF(ELC_EGP!Z$29="","",ELC_EGP!Z$29)+SUM($AC9:$AD9) -> 0.85102648 | Z9: =IF(ELC_EGP!AA$29="","",ELC_EGP!AA$29)+SUM($AC9:$AD9) -> 0.85102648 | AA9: =231.039345996009*(131.215852099895/100) -> 303.16025 | AB9: =45.0872552876596*(131.215852099895/100) -> 59.161626 | AC9: =0.45069361273084*(131.215852099895/100) -> 0.59138146 | AD9: =0.0909913043412747*(131.215852099895/100) -> 0.11939502 | AE9: =IF(ELC_EGP!AB$29="","",ELC_EGP!AB$29) -> 40 | AF9: =IF(ELC_EGP!AE$29="","",ELC_EGP!AE$29) -> 31.536 | AG9: =IF(ELC_EGP!AF$29="","",ELC_EGP!AF$29) -> 0.9 | AH9: =IF(ELC_EGP!AG$29="","",ELC_EGP!AG$29) | AI9: =IF(ELC_EGP!AH$29="","",ELC_EGP!AH$29) | AJ9: =IF(ELC_EGP!AI$29="","",ELC_EGP!AI$29) | AK9: =IF(ELC_EGP!AJ$29="","",ELC_EGP!AJ$29) | AO9: ELE | AP9: =B9 -> P-TH-SC-COA-CCS04-MP1 | AQ9: =C9 -> New Power Plant - Pulverised coal supercritical CCS post-combustion_Moneypoint Kinsale | AR9: PJ | AS9: GW | AT9: DAYNITE | AX9: ENV | AY9: PWRCO2S | AZ9: Sequestered CO2 (PWR) | BA9: kt | BG9: Pulverised coal supercritical CCS post-combustion_Moneypoint Kinsale
B10: P-TH-IGCC-COA-CCS06-MP1 | C10: ="New Power Plant - "&BG10 -> New Power Plant - IGCC coal CCS pre-combustion_Moneypoint Kinsale | D10: PWRCOA | E10: ="ELCC, "&$AY$9 -> ELCC, PWRCO2S | F10: =IF(ELC_EGP!G$32="","",ELC_EGP!G$32) -> 0.35 | G10: =IF(ELC_EGP!H$32="","",ELC_EGP!H$32) -> 0.37 | H10: =IF(ELC_EGP!I$32="","",ELC_EGP!I$32) -> 0.4 | I10: =IF(ELC_EGP!J$32="","",ELC_EGP!J$32) -> 0.41 | J10: =IF(ELC_EGP!K$32="","",ELC_EGP!K$32) -> 0.44 | K10: =IF(ELC_EGP!L$32="","",ELC_EGP!L$32) -> 2030 | N10: =IF(ELC_EGP!O$32="","",ELC_EGP!O$32)+SUM($AA10:$AB10) -> 2902.3219 | O10: =IF(ELC_EGP!P$32="","",ELC_EGP!P$32)+SUM($AA10:$AB10) -> 2582.3219 | P10: =IF(ELC_EGP!Q$32="","",ELC_EGP!Q$32)+SUM($AA10:$AB10) -> 2542.3219 | Q10: =IF(ELC_EGP!R$32="","",ELC_EGP!R$32) -> 93 | R10: =IF(ELC_EGP!S$32="","",ELC_EGP!S$32) -> 86.55 | S10: =IF(ELC_EGP!T$32="","",ELC_EGP!T$32) -> 84.75 | T10: =IF(ELC_EGP!U$32="","",ELC_EGP!U$32) -> 84.75 | U10: =IF(ELC_EGP!V$32="","",ELC_EGP!V$32) -> 84.75 | V10: =IF(ELC_EGP!W$32="","",ELC_EGP!W$32)+SUM($AC10:$AD10) -> 0.89677648 | W10: =IF(ELC_EGP!X$32="","",ELC_EGP!X$32)+SUM($AC10:$AD10) -> 0.88387648 | X10: =IF(ELC_EGP!Y$32="","",ELC_EGP!Y$32)+SUM($AC10:$AD10) -> 0.88027648 | Y10: =IF(ELC_EGP!Z$32="","",ELC_EGP!Z$32)+SUM($AC10:$AD10) -> 0.88027648 | Z10: =IF(ELC_EGP!AA$32="","",ELC_EGP!AA$32)+SUM($AC10:$AD10) -> 0.88027648 | AA10: =231.039345996009*(131.215852099895/100) -> 303.16025 | AB10: =45.0872552876596*(131.215852099895/100) -> 59.161626 | AC10: =0.45069361273084*(131.215852099895/100) -> 0.59138146 | AD10: =0.0909913043412747*(131.215852099895/100) -> 0.11939502 | AE10: =IF(ELC_EGP!AB$32="","",ELC_EGP!AB$32) -> 35 | AF10: =IF(ELC_EGP!AE$32="","",ELC_EGP!AE$32) -> 31.536 | AG10: =IF(ELC_EGP!AF$32="","",ELC_EGP!AF$32) -> 0.9 | AH10: =IF(ELC_EGP!AG$32="","",ELC_EGP!AG$32) | AI10: =IF(ELC_EGP!AH$32="","",ELC_EGP!AH$32) | AJ10: =IF(ELC_EGP!AI$32="","",ELC_EGP!AI$32) | AK10: =IF(ELC_EGP!AJ$32="","",ELC_EGP!AJ$32) | AO10: ELE | AP10: =B10 -> P-TH-IGCC-COA-CCS06-MP1 | AQ10: =C10 -> New Power Plant - IGCC coal CCS pre-combustion_Moneypoint Kinsale | AR10: PJ | AS10: GW | AT10: DAYNITE | BG10: IGCC coal CCS pre-combustion_Moneypoint Kinsale
B11: P-TH-SC-COA-CCS04-MP2 | C11: ="New Power Plant - "&BG11 -> New Power Plant - Pulverised coal supercritical CCS post-combustion_Moneypoint Spanish Point | D11: PWRCOA | E11: ="ELCC, "&$AY$9 -> ELCC, PWRCO2S | F11: =IF(ELC_EGP!G$29="","",ELC_EGP!G$29) -> 0.34 | G11: =IF(ELC_EGP!H$29="","",ELC_EGP!H$29) -> 0.35 | H11: =IF(ELC_EGP!I$29="","",ELC_EGP!I$29) -> 0.35 | I11: =IF(ELC_EGP!J$29="","",ELC_EGP!J$29) -> 0.38 | J11: =IF(ELC_EGP!K$29="","",ELC_EGP!K$29) -> 0.38 | K11: =IF(ELC_EGP!L$29="","",ELC_EGP!L$29) -> 2030 | N11: =IF(ELC_EGP!O$29="","",ELC_EGP!O$29)+SUM($AA11:$AB11) -> 3451.1153 | O11: =IF(ELC_EGP!P$29="","",ELC_EGP!P$29)+SUM($AA11:$AB11) -> 3301.1153 | P11: =IF(ELC_EGP!Q$29="","",ELC_EGP!Q$29)+SUM($AA11:$AB11) -> 3281.1153 | Q11: =IF(ELC_EGP!R$29="","",ELC_EGP!R$29) -> 75 | R11: =IF(ELC_EGP!S$29="","",ELC_EGP!S$29) -> 67.5 | S11: =IF(ELC_EGP!T$29="","",ELC_EGP!T$29) -> 63.75 | T11: =IF(ELC_EGP!U$29="","",ELC_EGP!U$29) -> 63.75 | U11: =IF(ELC_EGP!V$29="","",ELC_EGP!V$29) -> 63.75 | V11: =IF(ELC_EGP!W$29="","",ELC_EGP!W$29)+SUM($AC11:$AD11) -> 0.83067111 | W11: =IF(ELC_EGP!X$29="","",ELC_EGP!X$29)+SUM($AC11:$AD11) -> 0.81417111 | X11: =IF(ELC_EGP!Y$29="","",ELC_EGP!Y$29)+SUM($AC11:$AD11) -> 0.80592111 | Y11: =IF(ELC_EGP!Z$29="","",ELC_EGP!Z$29)+SUM($AC11:$AD11) -> 0.80592111 | Z11: =IF(ELC_EGP!AA$29="","",ELC_EGP!AA$29)+SUM($AC11:$AD11) -> 0.80592111 | AA11: =496.855906144888*(131.215852099895/100) -> 651.95371 | AB11: =45.0872552876596*(131.215852099895/100) -> 59.161626 | AC11: =0.416318676166623*(131.215852099895/100) -> 0.5462761 | AD11: =0.0909913043412747*(131.215852099895/100) -> 0.11939502 | AE11: =IF(ELC_EGP!AB$29="","",ELC_EGP!AB$29) -> 40 | AF11: =IF(ELC_EGP!AE$29="","",ELC_EGP!AE$29) -> 31.536 | AG11: =IF(ELC_EGP!AF$29="","",ELC_EGP!AF$29) -> 0.9 | AH11: =IF(ELC_EGP!AG$29="","",ELC_EGP!AG$29) | AI11: =IF(ELC_EGP!AH$29="","",ELC_EGP!AH$29) | AJ11: =IF(ELC_EGP!AI$29="","",ELC_EGP!AI$29) | AK11: =IF(ELC_EGP!AJ$29="","",ELC_EGP!AJ$29) | AO11: ELE | AP11: =B11 -> P-TH-SC-COA-CCS04-MP2 | AQ11: =C11 -> New Power Plant - Pulverised coal supercritical CCS post-combustion_Moneypoint Spanish Point | AR11: PJ | AS11: GW | AT11: DAYNITE | BG11: Pulverised coal supercritical CCS post-combustion_Moneypoint Spanish Point
B12: P-TH-IGCC-COA-CCS06-MP2 | C12: ="New Power Plant - "&BG12 -> New Power Plant - IGCC coal CCS pre-combustion_Moneypoint Spanish Point | D12: PWRCOA | E12: ="ELCC, "&$AY$9 -> ELCC, PWRCO2S | F12: =IF(ELC_EGP!G$32="","",ELC_EGP!G$32) -> 0.35 | G12: =IF(ELC_EGP!H$32="","",ELC_EGP!H$32) -> 0.37 | H12: =IF(ELC_EGP!I$32="","",ELC_EGP!I$32) -> 0.4 | I12: =IF(ELC_EGP!J$32="","",ELC_EGP!J$32) -> 0.41 | J12: =IF(ELC_EGP!K$32="","",ELC_EGP!K$32) -> 0.44 | K12: =IF(ELC_EGP!L$32="","",ELC_EGP!L$32) -> 2030 | N12: =IF(ELC_EGP!O$32="","",ELC_EGP!O$32)+SUM($AA12:$AB12) -> 3310.277 | O12: =IF(ELC_EGP!P$32="","",ELC_EGP!P$32)+SUM($AA12:$AB12) -> 2990.277 | P12: =IF(ELC_EGP!Q$32="","",ELC_EGP!Q$32)+SUM($AA12:$AB12) -> 2950.277 | Q12: =IF(ELC_EGP!R$32="","",ELC_EGP!R$32) -> 93 | R12: =IF(ELC_EGP!S$32="","",ELC_EGP!S$32) -> 86.55 | S12: =IF(ELC_EGP!T$32="","",ELC_EGP!T$32) -> 84.75 | T12: =IF(ELC_EGP!U$32="","",ELC_EGP!U$32) -> 84.75 | U12: =IF(ELC_EGP!V$32="","",ELC_EGP!V$32) -> 84.75 | V12: =IF(ELC_EGP!W$32="","",ELC_EGP!W$32)+SUM($AC12:$AD12) -> 0.85167111 | W12: =IF(ELC_EGP!X$32="","",ELC_EGP!X$32)+SUM($AC12:$AD12) -> 0.83877111 | X12: =IF(ELC_EGP!Y$32="","",ELC_EGP!Y$32)+SUM($AC12:$AD12) -> 0.83517111 | Y12: =IF(ELC_EGP!Z$32="","",ELC_EGP!Z$32)+SUM($AC12:$AD12) -> 0.83517111 | Z12: =IF(ELC_EGP!AA$32="","",ELC_EGP!AA$32)+SUM($AC12:$AD12) -> 0.83517111 | AA12: =496.855906144888*(131.215852099895/100) -> 651.95371 | AB12: =90.1745105753192*(131.215852099895/100) -> 118.32325 | AC12: =0.416318676166623*(131.215852099895/100) -> 0.5462761 | AD12: =0.0909913043412747*(131.215852099895/100) -> 0.11939502 | AE12: =IF(ELC_EGP!AB$32="","",ELC_EGP!AB$32) -> 35 | AF12: =IF(ELC_EGP!AE$32="","",ELC_EGP!AE$32) -> 31.536 | AG12: =IF(ELC_EGP!AF$32="","",ELC_EGP!AF$32) -> 0.9 | AH12: =IF(ELC_EGP!AG$32="","",ELC_EGP!AG$32) | AI12: =IF(ELC_EGP!AH$32="","",ELC_EGP!AH$32) | AJ12: =IF(ELC_EGP!AI$32="","",ELC_EGP!AI$32) | AK12: =IF(ELC_EGP!AJ$32="","",ELC_EGP!AJ$32) | AO12: ELE | AP12: =B12 -> P-TH-IGCC-COA-CCS06-MP2 | AQ12: =C12 -> New Power Plant - IGCC coal CCS pre-combustion_Moneypoint Spanish Point | AR12: PJ | AS12: GW | AT12: DAYNITE | BG12: IGCC coal CCS pre-combustion_Moneypoint Spanish Point
B13: P-TH-CCGT-GAS-CCS04-Cork1 | C13: ="New Power Plant - "&BG13 -> New Power Plant - CCGT advanced CCS post combustion_Cork Kinsale | D13: PWRGAS | E13: ="ELCC, "&$AY$9 -> ELCC, PWRCO2S | F13: =IF(ELC_EGP!G$28="","",ELC_EGP!G$28) -> 0.5 | G13: =IF(ELC_EGP!H$28="","",ELC_EGP!H$28) -> 0.52 | H13: =IF(ELC_EGP!I$28="","",ELC_EGP!I$28) -> 0.55 | I13: =IF(ELC_EGP!J$28="","",ELC_EGP!J$28) -> 0.55 | J13: =IF(ELC_EGP!K$28="","",ELC_EGP!K$28) -> 0.55 | K13: =IF(ELC_EGP!L$28="","",ELC_EGP!L$28) -> 2030 | N13: =IF(ELC_EGP!O$28="","",ELC_EGP!O$28)+SUM($AA13:$AB13) -> 1491.5259 | O13: =IF(ELC_EGP!P$28="","",ELC_EGP!P$28)+SUM($AA13:$AB13) -> 1411.5259 | P13: =IF(ELC_EGP!Q$28="","",ELC_EGP!Q$28)+SUM($AA13:$AB13) -> 1381.5259 | Q13: =IF(ELC_EGP!R$28="","",ELC_EGP!R$28) -> 37.5 | R13: =IF(ELC_EGP!S$28="","",ELC_EGP!S$28) -> 37.5 | S13: =IF(ELC_EGP!T$28="","",ELC_EGP!T$28) -> 37.5 | T13: =IF(ELC_EGP!U$28="","",ELC_EGP!U$28) -> 37.5 | U13: =IF(ELC_EGP!V$28="","",ELC_EGP!V$28) -> 37.5 | V13: =IF(ELC_EGP!W$28="","",ELC_EGP!W$28)+SUM($AC13:$AD13) -> 0.24714746 | W13: =IF(ELC_EGP!X$28="","",ELC_EGP!X$28)+SUM($AC13:$AD13) -> 0.24714746 | X13: =IF(ELC_EGP!Y$28="","",ELC_EGP!Y$28)+SUM($AC13:$AD13) -> 0.24714746 | Y13: =IF(ELC_EGP!Z$28="","",ELC_EGP!Z$28)+SUM($AC13:$AD13) -> 0.24714746 | Z13: =IF(ELC_EGP!AA$28="","",ELC_EGP!AA$28)+SUM($AC13:$AD13) -> 0.24714746 | AA13: =51.846136548894*(131.215852099895/100) -> 68.03035 | AB13: =25.5270389168779*(131.215852099895/100) -> 33.495522 | AC13: =0.0932556484566934*(131.215852099895/100) -> 0.12236619 | AD13: =0.0493699999964453*(131.215852099895/100) -> 0.064781266 | AE13: =IF(ELC_EGP!AB$28="","",ELC_EGP!AB$28) -> 30 | AF13: =IF(ELC_EGP!AE$28="","",ELC_EGP!AE$28) -> 31.536 | AG13: =IF(ELC_EGP!AF$28="","",ELC_EGP!AF$28) -> 0.9 | AH13: =IF(ELC_EGP!AG$28="","",ELC_EGP!AG$28) | AI13: =IF(ELC_EGP!AH$28="","",ELC_EGP!AH$28) | AJ13: =IF(ELC_EGP!AI$28="","",ELC_EGP!AI$28) | AK13: =IF(ELC_EGP!AJ$28="","",ELC_EGP!AJ$28) | AO13: ELE | AP13: =B13 -> P-TH-CCGT-GAS-CCS04-Cork1 | AQ13: =C13 -> New Power Plant - CCGT advanced CCS post combustion_Cork Kinsale | AR13: PJ | AS13: GW | AT13: DAYNITE | BG13: CCGT advanced CCS post combustion_Cork Kinsale
